ERROR 2024-11-11 05:12:35,417 log Internal Server Error: /api/tasks/
Traceback (most recent call last):
  File "/home/anumita/Github/task-tracker/.venv/lib/python3.12/site-packages/asgiref/sync.py", line 518, in thread_handler
    raise exc_info[1]
  File "/home/anumita/Github/task-tracker/.venv/lib/python3.12/site-packages/django/core/handlers/exception.py", line 42, in inner
    response = await get_response(request)
               ^^^^^^^^^^^^^^^^^^^^^^^^^^^
  File "/home/anumita/Github/task-tracker/.venv/lib/python3.12/site-packages/asgiref/sync.py", line 518, in thread_handler
    raise exc_info[1]
  File "/home/anumita/Github/task-tracker/.venv/lib/python3.12/site-packages/django/core/handlers/base.py", line 253, in _get_response_async
    response = await wrapped_callback(
               ^^^^^^^^^^^^^^^^^^^^^^^
  File "/home/anumita/Github/task-tracker/.venv/lib/python3.12/site-packages/asgiref/sync.py", line 468, in __call__
    ret = await asyncio.shield(exec_coro)
          ^^^^^^^^^^^^^^^^^^^^^^^^^^^^^^^
  File "/usr/lib/python3.12/concurrent/futures/thread.py", line 58, in run
    result = self.fn(*self.args, **self.kwargs)
             ^^^^^^^^^^^^^^^^^^^^^^^^^^^^^^^^^^
  File "/home/anumita/Github/task-tracker/.venv/lib/python3.12/site-packages/asgiref/sync.py", line 522, in thread_handler
    return func(*args, **kwargs)
           ^^^^^^^^^^^^^^^^^^^^^
  File "/home/anumita/Github/task-tracker/.venv/lib/python3.12/site-packages/django/views/decorators/csrf.py", line 65, in _view_wrapper
    return view_func(request, *args, **kwargs)
           ^^^^^^^^^^^^^^^^^^^^^^^^^^^^^^^^^^^
  File "/home/anumita/Github/task-tracker/.venv/lib/python3.12/site-packages/rest_framework/viewsets.py", line 124, in view
    return self.dispatch(request, *args, **kwargs)
           ^^^^^^^^^^^^^^^^^^^^^^^^^^^^^^^^^^^^^^^
  File "/home/anumita/Github/task-tracker/.venv/lib/python3.12/site-packages/rest_framework/views.py", line 509, in dispatch
    response = self.handle_exception(exc)
               ^^^^^^^^^^^^^^^^^^^^^^^^^^
  File "/home/anumita/Github/task-tracker/.venv/lib/python3.12/site-packages/rest_framework/views.py", line 469, in handle_exception
    self.raise_uncaught_exception(exc)
  File "/home/anumita/Github/task-tracker/.venv/lib/python3.12/site-packages/rest_framework/views.py", line 480, in raise_uncaught_exception
    raise exc
  File "/home/anumita/Github/task-tracker/.venv/lib/python3.12/site-packages/rest_framework/views.py", line 506, in dispatch
    response = handler(request, *args, **kwargs)
               ^^^^^^^^^^^^^^^^^^^^^^^^^^^^^^^^^
  File "/home/anumita/Github/task-tracker/tasks/views.py", line 25, in create
    self.perform_create(serializer)
  File "/home/anumita/Github/task-tracker/.venv/lib/python3.12/site-packages/rest_framework/mixins.py", line 24, in perform_create
    serializer.save()
  File "/home/anumita/Github/task-tracker/.venv/lib/python3.12/site-packages/rest_framework/serializers.py", line 176, in save
    assert hasattr(self, '_errors'), (
           ^^^^^^^^^^^^^^^^^^^^^^^^
AssertionError: You must call `.is_valid()` before calling `.save()`.
ERROR 2024-11-11 05:13:03,004 log Internal Server Error: /api/tasks/
Traceback (most recent call last):
  File "/home/anumita/Github/task-tracker/.venv/lib/python3.12/site-packages/asgiref/sync.py", line 518, in thread_handler
    raise exc_info[1]
  File "/home/anumita/Github/task-tracker/.venv/lib/python3.12/site-packages/django/core/handlers/exception.py", line 42, in inner
    response = await get_response(request)
               ^^^^^^^^^^^^^^^^^^^^^^^^^^^
  File "/home/anumita/Github/task-tracker/.venv/lib/python3.12/site-packages/asgiref/sync.py", line 518, in thread_handler
    raise exc_info[1]
  File "/home/anumita/Github/task-tracker/.venv/lib/python3.12/site-packages/django/core/handlers/base.py", line 253, in _get_response_async
    response = await wrapped_callback(
               ^^^^^^^^^^^^^^^^^^^^^^^
  File "/home/anumita/Github/task-tracker/.venv/lib/python3.12/site-packages/asgiref/sync.py", line 468, in __call__
    ret = await asyncio.shield(exec_coro)
          ^^^^^^^^^^^^^^^^^^^^^^^^^^^^^^^
  File "/usr/lib/python3.12/concurrent/futures/thread.py", line 58, in run
    result = self.fn(*self.args, **self.kwargs)
             ^^^^^^^^^^^^^^^^^^^^^^^^^^^^^^^^^^
  File "/home/anumita/Github/task-tracker/.venv/lib/python3.12/site-packages/asgiref/sync.py", line 522, in thread_handler
    return func(*args, **kwargs)
           ^^^^^^^^^^^^^^^^^^^^^
  File "/home/anumita/Github/task-tracker/.venv/lib/python3.12/site-packages/django/views/decorators/csrf.py", line 65, in _view_wrapper
    return view_func(request, *args, **kwargs)
           ^^^^^^^^^^^^^^^^^^^^^^^^^^^^^^^^^^^
  File "/home/anumita/Github/task-tracker/.venv/lib/python3.12/site-packages/rest_framework/viewsets.py", line 124, in view
    return self.dispatch(request, *args, **kwargs)
           ^^^^^^^^^^^^^^^^^^^^^^^^^^^^^^^^^^^^^^^
  File "/home/anumita/Github/task-tracker/.venv/lib/python3.12/site-packages/rest_framework/views.py", line 511, in dispatch
    self.response = self.finalize_response(request, response, *args, **kwargs)
                    ^^^^^^^^^^^^^^^^^^^^^^^^^^^^^^^^^^^^^^^^^^^^^^^^^^^^^^^^^^
  File "/home/anumita/Github/task-tracker/.venv/lib/python3.12/site-packages/rest_framework/views.py", line 423, in finalize_response
    assert isinstance(response, HttpResponseBase), (
           ^^^^^^^^^^^^^^^^^^^^^^^^^^^^^^^^^^^^^^
AssertionError: Expected a `Response`, `HttpResponse` or `StreamingHttpResponse` to be returned from the view, but received a `<class 'NoneType'>`
ERROR 2024-11-11 05:13:35,420 log Internal Server Error: /api/tasks/
Traceback (most recent call last):
  File "/home/anumita/Github/task-tracker/.venv/lib/python3.12/site-packages/asgiref/sync.py", line 518, in thread_handler
    raise exc_info[1]
  File "/home/anumita/Github/task-tracker/.venv/lib/python3.12/site-packages/django/core/handlers/exception.py", line 42, in inner
    response = await get_response(request)
               ^^^^^^^^^^^^^^^^^^^^^^^^^^^
  File "/home/anumita/Github/task-tracker/.venv/lib/python3.12/site-packages/asgiref/sync.py", line 518, in thread_handler
    raise exc_info[1]
  File "/home/anumita/Github/task-tracker/.venv/lib/python3.12/site-packages/django/core/handlers/base.py", line 253, in _get_response_async
    response = await wrapped_callback(
               ^^^^^^^^^^^^^^^^^^^^^^^
  File "/home/anumita/Github/task-tracker/.venv/lib/python3.12/site-packages/asgiref/sync.py", line 468, in __call__
    ret = await asyncio.shield(exec_coro)
          ^^^^^^^^^^^^^^^^^^^^^^^^^^^^^^^
  File "/usr/lib/python3.12/concurrent/futures/thread.py", line 58, in run
    result = self.fn(*self.args, **self.kwargs)
             ^^^^^^^^^^^^^^^^^^^^^^^^^^^^^^^^^^
  File "/home/anumita/Github/task-tracker/.venv/lib/python3.12/site-packages/asgiref/sync.py", line 522, in thread_handler
    return func(*args, **kwargs)
           ^^^^^^^^^^^^^^^^^^^^^
  File "/home/anumita/Github/task-tracker/.venv/lib/python3.12/site-packages/django/views/decorators/csrf.py", line 65, in _view_wrapper
    return view_func(request, *args, **kwargs)
           ^^^^^^^^^^^^^^^^^^^^^^^^^^^^^^^^^^^
  File "/home/anumita/Github/task-tracker/.venv/lib/python3.12/site-packages/rest_framework/viewsets.py", line 124, in view
    return self.dispatch(request, *args, **kwargs)
           ^^^^^^^^^^^^^^^^^^^^^^^^^^^^^^^^^^^^^^^
  File "/home/anumita/Github/task-tracker/.venv/lib/python3.12/site-packages/rest_framework/views.py", line 509, in dispatch
    response = self.handle_exception(exc)
               ^^^^^^^^^^^^^^^^^^^^^^^^^^
  File "/home/anumita/Github/task-tracker/.venv/lib/python3.12/site-packages/rest_framework/views.py", line 469, in handle_exception
    self.raise_uncaught_exception(exc)
  File "/home/anumita/Github/task-tracker/.venv/lib/python3.12/site-packages/rest_framework/views.py", line 480, in raise_uncaught_exception
    raise exc
  File "/home/anumita/Github/task-tracker/.venv/lib/python3.12/site-packages/rest_framework/views.py", line 506, in dispatch
    response = handler(request, *args, **kwargs)
               ^^^^^^^^^^^^^^^^^^^^^^^^^^^^^^^^^
  File "/home/anumita/Github/task-tracker/tasks/views.py", line 28, in create
    return Response(serializer.errors, status=status.HTTP_400_BAD_REQUEST)
           ^^^^^^^^
NameError: name 'Response' is not defined
ERROR 2024-11-11 05:16:18,761 log Internal Server Error: /api/tasks/
Traceback (most recent call last):
  File "/home/anumita/Github/task-tracker/.venv/lib/python3.12/site-packages/rest_framework/request.py", line 421, in __getattr__
    return getattr(_request, attr)
           ^^^^^^^^^^^^^^^^^^^^^^^
AttributeError: 'ASGIRequest' object has no attribute 'keys'

During handling of the above exception, another exception occurred:

Traceback (most recent call last):
  File "/home/anumita/Github/task-tracker/.venv/lib/python3.12/site-packages/asgiref/sync.py", line 518, in thread_handler
    raise exc_info[1]
  File "/home/anumita/Github/task-tracker/.venv/lib/python3.12/site-packages/django/core/handlers/exception.py", line 42, in inner
    response = await get_response(request)
               ^^^^^^^^^^^^^^^^^^^^^^^^^^^
  File "/home/anumita/Github/task-tracker/.venv/lib/python3.12/site-packages/asgiref/sync.py", line 518, in thread_handler
    raise exc_info[1]
  File "/home/anumita/Github/task-tracker/.venv/lib/python3.12/site-packages/django/core/handlers/base.py", line 253, in _get_response_async
    response = await wrapped_callback(
               ^^^^^^^^^^^^^^^^^^^^^^^
  File "/home/anumita/Github/task-tracker/.venv/lib/python3.12/site-packages/asgiref/sync.py", line 468, in __call__
    ret = await asyncio.shield(exec_coro)
          ^^^^^^^^^^^^^^^^^^^^^^^^^^^^^^^
  File "/usr/lib/python3.12/concurrent/futures/thread.py", line 58, in run
    result = self.fn(*self.args, **self.kwargs)
             ^^^^^^^^^^^^^^^^^^^^^^^^^^^^^^^^^^
  File "/home/anumita/Github/task-tracker/.venv/lib/python3.12/site-packages/asgiref/sync.py", line 522, in thread_handler
    return func(*args, **kwargs)
           ^^^^^^^^^^^^^^^^^^^^^
  File "/home/anumita/Github/task-tracker/.venv/lib/python3.12/site-packages/django/views/decorators/csrf.py", line 65, in _view_wrapper
    return view_func(request, *args, **kwargs)
           ^^^^^^^^^^^^^^^^^^^^^^^^^^^^^^^^^^^
  File "/home/anumita/Github/task-tracker/.venv/lib/python3.12/site-packages/rest_framework/viewsets.py", line 124, in view
    return self.dispatch(request, *args, **kwargs)
           ^^^^^^^^^^^^^^^^^^^^^^^^^^^^^^^^^^^^^^^
  File "/home/anumita/Github/task-tracker/.venv/lib/python3.12/site-packages/rest_framework/views.py", line 509, in dispatch
    response = self.handle_exception(exc)
               ^^^^^^^^^^^^^^^^^^^^^^^^^^
  File "/home/anumita/Github/task-tracker/.venv/lib/python3.12/site-packages/rest_framework/views.py", line 469, in handle_exception
    self.raise_uncaught_exception(exc)
  File "/home/anumita/Github/task-tracker/.venv/lib/python3.12/site-packages/rest_framework/views.py", line 480, in raise_uncaught_exception
    raise exc
  File "/home/anumita/Github/task-tracker/.venv/lib/python3.12/site-packages/rest_framework/views.py", line 506, in dispatch
    response = handler(request, *args, **kwargs)
               ^^^^^^^^^^^^^^^^^^^^^^^^^^^^^^^^^
  File "/home/anumita/Github/task-tracker/tasks/views.py", line 25, in create
    print([k for k in request.keys()])
                      ^^^^^^^^^^^^
  File "/home/anumita/Github/task-tracker/.venv/lib/python3.12/site-packages/rest_framework/request.py", line 423, in __getattr__
    return self.__getattribute__(attr)
           ^^^^^^^^^^^^^^^^^^^^^^^^^^^
AttributeError: 'Request' object has no attribute 'keys'
ERROR 2024-11-11 05:25:36,535 log Internal Server Error: /api/tasks/
Traceback (most recent call last):
  File "/home/anumita/Github/task-tracker/.venv/lib/python3.12/site-packages/asgiref/sync.py", line 518, in thread_handler
    raise exc_info[1]
  File "/home/anumita/Github/task-tracker/.venv/lib/python3.12/site-packages/django/core/handlers/exception.py", line 42, in inner
    response = await get_response(request)
               ^^^^^^^^^^^^^^^^^^^^^^^^^^^
  File "/home/anumita/Github/task-tracker/.venv/lib/python3.12/site-packages/asgiref/sync.py", line 518, in thread_handler
    raise exc_info[1]
  File "/home/anumita/Github/task-tracker/.venv/lib/python3.12/site-packages/django/core/handlers/base.py", line 253, in _get_response_async
    response = await wrapped_callback(
               ^^^^^^^^^^^^^^^^^^^^^^^
  File "/home/anumita/Github/task-tracker/.venv/lib/python3.12/site-packages/asgiref/sync.py", line 468, in __call__
    ret = await asyncio.shield(exec_coro)
          ^^^^^^^^^^^^^^^^^^^^^^^^^^^^^^^
  File "/usr/lib/python3.12/concurrent/futures/thread.py", line 58, in run
    result = self.fn(*self.args, **self.kwargs)
             ^^^^^^^^^^^^^^^^^^^^^^^^^^^^^^^^^^
  File "/home/anumita/Github/task-tracker/.venv/lib/python3.12/site-packages/asgiref/sync.py", line 522, in thread_handler
    return func(*args, **kwargs)
           ^^^^^^^^^^^^^^^^^^^^^
  File "/home/anumita/Github/task-tracker/.venv/lib/python3.12/site-packages/django/views/decorators/csrf.py", line 65, in _view_wrapper
    return view_func(request, *args, **kwargs)
           ^^^^^^^^^^^^^^^^^^^^^^^^^^^^^^^^^^^
  File "/home/anumita/Github/task-tracker/.venv/lib/python3.12/site-packages/rest_framework/viewsets.py", line 124, in view
    return self.dispatch(request, *args, **kwargs)
           ^^^^^^^^^^^^^^^^^^^^^^^^^^^^^^^^^^^^^^^
  File "/home/anumita/Github/task-tracker/.venv/lib/python3.12/site-packages/rest_framework/views.py", line 509, in dispatch
    response = self.handle_exception(exc)
               ^^^^^^^^^^^^^^^^^^^^^^^^^^
  File "/home/anumita/Github/task-tracker/.venv/lib/python3.12/site-packages/rest_framework/views.py", line 469, in handle_exception
    self.raise_uncaught_exception(exc)
  File "/home/anumita/Github/task-tracker/.venv/lib/python3.12/site-packages/rest_framework/views.py", line 480, in raise_uncaught_exception
    raise exc
  File "/home/anumita/Github/task-tracker/.venv/lib/python3.12/site-packages/rest_framework/views.py", line 506, in dispatch
    response = handler(request, *args, **kwargs)
               ^^^^^^^^^^^^^^^^^^^^^^^^^^^^^^^^^
  File "/home/anumita/Github/task-tracker/tasks/views.py", line 28, in create
    print(request.data["tags"])
          ~~~~~~~~~~~~^^^^^^^^
KeyError: 'tags'
ERROR 2024-11-11 05:26:31,278 log Internal Server Error: /api/tasks/
Traceback (most recent call last):
  File "/home/anumita/Github/task-tracker/.venv/lib/python3.12/site-packages/asgiref/sync.py", line 518, in thread_handler
    raise exc_info[1]
  File "/home/anumita/Github/task-tracker/.venv/lib/python3.12/site-packages/django/core/handlers/exception.py", line 42, in inner
    response = await get_response(request)
               ^^^^^^^^^^^^^^^^^^^^^^^^^^^
  File "/home/anumita/Github/task-tracker/.venv/lib/python3.12/site-packages/asgiref/sync.py", line 518, in thread_handler
    raise exc_info[1]
  File "/home/anumita/Github/task-tracker/.venv/lib/python3.12/site-packages/django/core/handlers/base.py", line 253, in _get_response_async
    response = await wrapped_callback(
               ^^^^^^^^^^^^^^^^^^^^^^^
  File "/home/anumita/Github/task-tracker/.venv/lib/python3.12/site-packages/asgiref/sync.py", line 468, in __call__
    ret = await asyncio.shield(exec_coro)
          ^^^^^^^^^^^^^^^^^^^^^^^^^^^^^^^
  File "/usr/lib/python3.12/concurrent/futures/thread.py", line 58, in run
    result = self.fn(*self.args, **self.kwargs)
             ^^^^^^^^^^^^^^^^^^^^^^^^^^^^^^^^^^
  File "/home/anumita/Github/task-tracker/.venv/lib/python3.12/site-packages/asgiref/sync.py", line 522, in thread_handler
    return func(*args, **kwargs)
           ^^^^^^^^^^^^^^^^^^^^^
  File "/home/anumita/Github/task-tracker/.venv/lib/python3.12/site-packages/django/views/decorators/csrf.py", line 65, in _view_wrapper
    return view_func(request, *args, **kwargs)
           ^^^^^^^^^^^^^^^^^^^^^^^^^^^^^^^^^^^
  File "/home/anumita/Github/task-tracker/.venv/lib/python3.12/site-packages/rest_framework/viewsets.py", line 124, in view
    return self.dispatch(request, *args, **kwargs)
           ^^^^^^^^^^^^^^^^^^^^^^^^^^^^^^^^^^^^^^^
  File "/home/anumita/Github/task-tracker/.venv/lib/python3.12/site-packages/rest_framework/views.py", line 509, in dispatch
    response = self.handle_exception(exc)
               ^^^^^^^^^^^^^^^^^^^^^^^^^^
  File "/home/anumita/Github/task-tracker/.venv/lib/python3.12/site-packages/rest_framework/views.py", line 469, in handle_exception
    self.raise_uncaught_exception(exc)
  File "/home/anumita/Github/task-tracker/.venv/lib/python3.12/site-packages/rest_framework/views.py", line 480, in raise_uncaught_exception
    raise exc
  File "/home/anumita/Github/task-tracker/.venv/lib/python3.12/site-packages/rest_framework/views.py", line 506, in dispatch
    response = handler(request, *args, **kwargs)
               ^^^^^^^^^^^^^^^^^^^^^^^^^^^^^^^^^
  File "/home/anumita/Github/task-tracker/tasks/views.py", line 28, in create
    print(request.data["tags"])
          ~~~~~~~~~~~~^^^^^^^^
KeyError: 'tags'
ERROR 2024-11-12 08:19:11,647 log Internal Server Error: /api/tasks/
Traceback (most recent call last):
  File "/home/anumita/Github/task-tracker/.venv/lib/python3.12/site-packages/asgiref/sync.py", line 518, in thread_handler
    raise exc_info[1]
  File "/home/anumita/Github/task-tracker/.venv/lib/python3.12/site-packages/django/core/handlers/exception.py", line 42, in inner
    response = await get_response(request)
               ^^^^^^^^^^^^^^^^^^^^^^^^^^^
  File "/home/anumita/Github/task-tracker/.venv/lib/python3.12/site-packages/asgiref/sync.py", line 518, in thread_handler
    raise exc_info[1]
  File "/home/anumita/Github/task-tracker/.venv/lib/python3.12/site-packages/django/core/handlers/base.py", line 253, in _get_response_async
    response = await wrapped_callback(
               ^^^^^^^^^^^^^^^^^^^^^^^
  File "/home/anumita/Github/task-tracker/.venv/lib/python3.12/site-packages/asgiref/sync.py", line 468, in __call__
    ret = await asyncio.shield(exec_coro)
          ^^^^^^^^^^^^^^^^^^^^^^^^^^^^^^^
  File "/usr/lib/python3.12/concurrent/futures/thread.py", line 58, in run
    result = self.fn(*self.args, **self.kwargs)
             ^^^^^^^^^^^^^^^^^^^^^^^^^^^^^^^^^^
  File "/home/anumita/Github/task-tracker/.venv/lib/python3.12/site-packages/asgiref/sync.py", line 522, in thread_handler
    return func(*args, **kwargs)
           ^^^^^^^^^^^^^^^^^^^^^
  File "/home/anumita/Github/task-tracker/.venv/lib/python3.12/site-packages/django/views/decorators/csrf.py", line 65, in _view_wrapper
    return view_func(request, *args, **kwargs)
           ^^^^^^^^^^^^^^^^^^^^^^^^^^^^^^^^^^^
  File "/home/anumita/Github/task-tracker/.venv/lib/python3.12/site-packages/rest_framework/viewsets.py", line 124, in view
    return self.dispatch(request, *args, **kwargs)
           ^^^^^^^^^^^^^^^^^^^^^^^^^^^^^^^^^^^^^^^
  File "/home/anumita/Github/task-tracker/.venv/lib/python3.12/site-packages/rest_framework/views.py", line 509, in dispatch
    response = self.handle_exception(exc)
               ^^^^^^^^^^^^^^^^^^^^^^^^^^
  File "/home/anumita/Github/task-tracker/.venv/lib/python3.12/site-packages/rest_framework/views.py", line 469, in handle_exception
    self.raise_uncaught_exception(exc)
  File "/home/anumita/Github/task-tracker/.venv/lib/python3.12/site-packages/rest_framework/views.py", line 480, in raise_uncaught_exception
    raise exc
  File "/home/anumita/Github/task-tracker/.venv/lib/python3.12/site-packages/rest_framework/views.py", line 506, in dispatch
    response = handler(request, *args, **kwargs)
               ^^^^^^^^^^^^^^^^^^^^^^^^^^^^^^^^^
  File "/home/anumita/Github/task-tracker/tasks/views.py", line 28, in create
    print(request.data["tag_ids"])
          ~~~~~~~~~~~~^^^^^^^^^^^
KeyError: 'tag_ids'
